<?xml version="1.0" ?>
<robot name="panda" xmlns:xacro="http://www.ros.org/wiki/xacro">
  <!-- Used in Diana Arm -->
  <material name="arm_color">
    <color rgba="0.439 0.497 0.629 1.0"/>
  </material>

  <material name="palm_color">
    <color rgba="0.190 0.239 0.274 1.0"/>
  </material>

  <material name="phaprox_color">
    <color rgba="0.077 0.288 0.348 1.0"/>
  </material>

  <material name="phadist_color">
    <color rgba="0.458 0.674 0.772 1.0"/>
  </material>

  <material name="phamed_color">
    <color rgba="0.213 0.592 0.701 1.0"/>
  </material>
  
  <link name="panda_link0">
    <visual>
      <geometry>
        <mesh filename="./meshes/visual/panda/link0.dae"/>
      </geometry>
    </visual>
    <collision>
      <geometry>
        <mesh filename="./meshes/collision/panda/link0.stl"/>
      </geometry>
    </collision>
    <inertial>
      <origin rpy="0 0 0" xyz="0 0 0"/>
      <mass value="2.8142028896"/>
      <inertia ixx="0.0129886979" ixy="0.0" ixz="0.0" iyy="0.0165355284" iyz="0" izz="0.0203311636"/>
    </inertial>
  </link>
  <link name="panda_link1">
    <visual>
      <geometry>
        <mesh filename="./meshes/visual/panda/link1.dae"/>
      </geometry>
    </visual>
    <collision>
      <geometry>
        <mesh filename="./meshes/collision/panda/link1.stl"/>
      </geometry>
    </collision>
    <inertial>
      <origin rpy="0 0 0" xyz="0 0 0"/>
      <mass value="2.3599995791"/>
      <inertia ixx="0.0186863903" ixy="0.0" ixz="0.0" iyy="0.0143789874" iyz="0" izz="0.00906812"/>
    </inertial>
  </link>
  <joint name="panda_joint1" type="revolute">
    <safety_controller k_position="100.0" k_velocity="40.0" soft_lower_limit="-2.8973" soft_upper_limit="2.8973"/>
    <origin rpy="0 0 0" xyz="0 0 0.333"/>
    <parent link="panda_link0"/>
    <child link="panda_link1"/>
    <axis xyz="0 0 1"/>
    <limit effort="87" lower="-2.8973" upper="2.8973" velocity="2.1750"/>
  </joint>
  <link name="panda_link2">
    <visual>
      <geometry>
        <mesh filename="./meshes/visual/panda/link2.dae"/>
      </geometry>
    </visual>
    <collision>
      <geometry>
        <mesh filename="./meshes/collision/panda/link2.stl"/>
      </geometry>
    </collision>
    <inertial>
      <origin rpy="0 0 0" xyz="0 0 0"/>
      <mass value="2.379518833"/>
      <inertia ixx="0.0190388734" ixy="0.0" ixz="0.0" iyy="0.0091429124" iyz="0" izz="0.014697537"/>
    </inertial>
  </link>
  <joint name="panda_joint2" type="revolute">
    <safety_controller k_position="100.0" k_velocity="40.0" soft_lower_limit="-1.7628" soft_upper_limit="1.7628"/>
    <origin rpy="-1.57079632679 0 0" xyz="0 0 0"/>
    <parent link="panda_link1"/>
    <child link="panda_link2"/>
    <axis xyz="0 0 1"/>
    <limit effort="87" lower="-1.7628" upper="1.7628" velocity="2.1750"/>
  </joint>
  <link name="panda_link3">
    <visual>
      <geometry>
        <mesh filename="./meshes/visual/panda/link3.dae"/>
      </geometry>
    </visual>
    <collision>
      <geometry>
        <mesh filename="./meshes/collision/panda/link3.stl"/>
      </geometry>
    </collision>
    <inertial>
      <origin rpy="0 0 0" xyz="0 0 0"/>
      <mass value="2.6498823337"/>
      <inertia ixx="0.0129300178" ixy="0.0" ixz="0.0" iyy="0.0150242121" iyz="0" izz="0.0142734598"/>
    </inertial>
  </link>
  <joint name="panda_joint3" type="revolute">
    <safety_controller k_position="100.0" k_velocity="40.0" soft_lower_limit="-2.8973" soft_upper_limit="2.8973"/>
    <origin rpy="1.57079632679 0 0" xyz="0 -0.316 0"/>
    <parent link="panda_link2"/>
    <child link="panda_link3"/>
    <axis xyz="0 0 1"/>
    <limit effort="87" lower="-2.8973" upper="2.8973" velocity="2.1750"/>
  </joint>
  <link name="panda_link4">
    <visual>
      <geometry>
        <mesh filename="./meshes/visual/panda/link4.dae"/>
      </geometry>
    </visual>
    <collision>
      <geometry>
        <mesh filename="./meshes/collision/panda/link4.stl"/>
      </geometry>
    </collision>
    <inertial>
      <origin rpy="0 0 0" xyz="0 0 0"/>
      <mass value="2.6948018744"/>
      <inertia ixx="0.0133874611" ixy="0.0" ixz="0.0" iyy="0.014514325" iyz="0" izz="0.0155175551"/>
    </inertial>
  </link>
  <joint name="panda_joint4" type="revolute">
    <safety_controller k_position="100.0" k_velocity="40.0" soft_lower_limit="-3.0718" soft_upper_limit="-0.0698"/>
    <origin rpy="1.57079632679 0 0" xyz="0.0825 0 0"/>
    <parent link="panda_link3"/>
    <child link="panda_link4"/>
    <axis xyz="0 0 1"/>
    <limit effort="87" lower="-3.0718" upper="-0.0698" velocity="2.1750"/>
  </joint>
  <link name="panda_link5">
    <visual>
      <geometry>
        <mesh filename="./meshes/visual/panda/link5.dae"/>
      </geometry>
    </visual>
    <collision>
      <geometry>
        <mesh filename="./meshes/collision/panda/link5.stl"/>
      </geometry>
    </collision>
    <inertial>
      <origin rpy="0 0 0" xyz="0 0 0"/>
      <mass value="2.9812816864"/>
      <inertia ixx="0.0325565705" ixy="0.0" ixz="0.0" iyy="0.0270660472" iyz="0" izz="0.0115023375"/>
    </inertial>
  </link>
  <joint name="panda_joint5" type="revolute">
    <safety_controller k_position="100.0" k_velocity="40.0" soft_lower_limit="-2.8973" soft_upper_limit="2.8973"/>
    <origin rpy="-1.57079632679 0 0" xyz="-0.0825 0.384 0"/>
    <parent link="panda_link4"/>
    <child link="panda_link5"/>
    <axis xyz="0 0 1"/>
    <limit effort="12" lower="-2.8973" upper="2.8973" velocity="2.6100"/>
  </joint>
  <link name="panda_link6">
    <visual>
      <geometry>
        <mesh filename="./meshes/visual/panda/link6.dae"/>
      </geometry>
    </visual>
    <collision>
      <geometry>
        <mesh filename="./meshes/collision/panda/link6.stl"/>
      </geometry>
    </collision>
    <inertial>
      <origin rpy="0 0 0" xyz="0 0 0"/>
      <mass value="1.1285806309"/>
      <inertia ixx="0.0026052565" ixy="0.0" ixz="0.0" iyy="0.0039897229" iyz="0" izz="0.0047048591"/>
    </inertial>
  </link>
  <joint name="panda_joint6" type="revolute">
    <safety_controller k_position="100.0" k_velocity="40.0" soft_lower_limit="-0.0175" soft_upper_limit="3.7525"/>
    <origin rpy="1.57079632679 0 0" xyz="0 0 0"/>
    <parent link="panda_link5"/>
    <child link="panda_link6"/>
    <axis xyz="0 0 1"/>
    <limit effort="12" lower="-0.0175" upper="3.7525" velocity="2.6100"/>
  </joint>
  <link name="panda_link7">
    <visual>
      <geometry>
        <mesh filename="./meshes/visual/panda/link7.dae"/>
      </geometry>
    </visual>
    <collision>
      <geometry>
        <mesh filename="./meshes/collision/panda/link7.stl"/>
      </geometry>
    </collision>
    <inertial>
      <origin rpy="0 0 0" xyz="0 0 0"/>
      <mass value="0.4052912465"/>
      <inertia ixx="0.0006316592" ixy="0.0" ixz="0.0" iyy="0.0006319639" iyz="0" izz="0.0010607721"/>
    </inertial>
  </link>
  <joint name="panda_joint7" type="revolute">
    <safety_controller k_position="100.0" k_velocity="40.0" soft_lower_limit="-2.8973" soft_upper_limit="2.8973"/>
    <origin rpy="1.57079632679 0 0" xyz="0.088 0 0"/>
    <parent link="panda_link6"/>
    <child link="panda_link7"/>
    <axis xyz="0 0 1"/>
    <limit effort="12" lower="-2.8973" upper="2.8973" velocity="2.6100"/>
  </joint>
  <link name="panda_link8"/>
  <joint name="panda_joint8" type="fixed">
    <origin rpy="0 0 0" xyz="0 0 0.107"/>
    <parent link="panda_link7"/>
    <child link="panda_link8"/>
    <axis xyz="0 0 0"/>
  </joint>
    <joint name="hand_joint" type="fixed">
    <origin rpy="0 0 -1.57" xyz="0 0 0"/>
    <parent link="panda_link8"/>
    <child link="base_link_hithand"/>
    <axis xyz="0 0 0"/>
  </joint>
<!-- ++++ Define all the links and joints ++++ -->
  <link name="base_link_hithand">
    <inertial>
      <origin rpy="0 0 0" xyz="0.0112 0.0 0.0566"/>
      <mass value="1.1485"/>
      <inertia ixx="2.2458e-3" ixy="-2.7421e-4" ixz="1.6e-5" iyy="2.2203e-3" iyz="-6.37e-5" izz="1.9003e-3"/>
    </inertial>
    <visual>
      <origin rpy="0 0 0" xyz="0 0 0"/>
      <geometry>
        <mesh filename="./meshes/visual/tekken/palm-right.dae"/>
      </geometry>
      <!-- <material name="palm_color"/> -->
    </visual>
    <collision>
      <origin rpy="-1.57 0 0" xyz="0 0 0"/>
      <geometry>
        <mesh filename="./meshes/collision/tekken/hit-hand-2-palm-right.stl"/>
      </geometry>
    </collision>
  </link>
  <!-- Add a virtual palm link to get the transform of this point via TF for grasping (we align this frame with
        a normal of a point from an object point cloud.) -->
  <joint name="hithand_palm_joint" type="fixed">
    <parent link="base_link_hithand"/>
    <child link="palm_link_hithand"/>
    <origin rpy="-1.57 -1.57 0" xyz="0.02 0 0.06"/>
  </joint>
  <link name="palm_link_hithand"/>
  <!-- #########################FINGER######################## -->
  <!-- END of finger macro -->
  <!-- +++++ Finger base joint 0 ++++++ -->
  <joint name="Right_Thumb_0" type="revolute">
    <!-- joint origin in parent link frame -->
    <origin rpy="0.225810 -1.083656 0.411355" xyz="0.06217593 0.044372912 0.078734808"/>
    <parent link="base_link_hithand"/>
    <child link="Right_Thumb_Basecover"/>
    <axis xyz="0 0 1"/>
    <limit effort="15" lower="-0.261799" upper="0.261799" velocity="3.14"/>
    <dynamics damping="0.5" friction="0"/>
  </joint>
  <link name="Right_Thumb_Basecover">
    <inertial>
      <origin rpy="0 0 0" xyz="0.02749 0 0"/>
      <mass value="0.0176"/>
      <inertia ixx="1.3450e-6" ixy="0.0" ixz="-1.8183e-7" iyy="1.9874e-6" iyz="0.0" izz="1.0419e-6"/>
    </inertial>
    <visual>
      <origin rpy="0 0 0" xyz="0 0 0"/>
      <geometry>
        <mesh filename="./meshes/visual/tekken/finger-basecover.dae"/>
      </geometry>
      <!-- <material name="phaprox_color"/> -->
    </visual>
    <collision>
      <origin rpy="0 0 0" xyz="0 0 0"/>
      <geometry name="hithand_Thumb_base_cover">
        <cylinder length="0.001" radius="0.001"/>
      </geometry>
    </collision>
  </link>
  <!-- +++++ Finger joint 1, Link: Phalanx proximalis ++++++ -->
  <joint name="Right_Thumb_1" type="revolute">
    <origin rpy="1.5708 0 0" xyz="0 0 0 "/>
    <parent link="Right_Thumb_Basecover"/>
    <child link="Right_Thumb_Phaprox"/>
    <axis xyz="0 0 1"/>
    <limit effort="1.15" lower="0.0" upper="1.48353" velocity="3.14"/>
    <!-- Effort limit based on max fingertip force of 10N. Finger tip is approx 11.5cm away from this joint.-->
    <dynamics damping="0.5" friction="0"/>
  </joint>
  <link name="Right_Thumb_Phaprox">
    <inertial>
      <origin rpy="0 0 0" xyz="0.02516 -0.0019 0"/>
      <mass value="0.0571"/>
      <inertia ixx="5.7609e-6" ixy="-4.3826e-7" ixz="-3.2556e-7" iyy="1.5809e-5" iyz="-4.516e-8" izz="1.8139e-5"/>
    </inertial>
    <visual>
      <origin rpy="0 0 0" xyz="0 0 0"/>
      <geometry>
        <mesh filename="./meshes/visual/tekken/finger-phaprox.dae"/>
      </geometry>
      <!-- <material name="phaprox_color"/> -->
    </visual>
    <collision>
      <origin rpy="0 0 0" xyz="0 0 0"/>
      <geometry>
        <mesh filename="./meshes/collision/tekken/finger-phaprox.obj"/>
      </geometry>
    </collision>
  </link>
  <!-- +++++ Finger joint 2 Phalanx medialis ++++++ -->
  <joint name="Right_Thumb_2" type="revolute">
    <origin rpy="0 0 0" xyz="0.055 0 0"/>
    <parent link="Right_Thumb_Phaprox"/>
    <child link="Right_Thumb_Phamed"/>
    <axis xyz="0 0 1"/>
    <limit effort="0.6" lower="0.0" upper="1.13446" velocity="3.14"/>
    <!-- Effort limit based on max fingertip force of 10N. Finger tip is approx 6cm away from this joint.-->
    <dynamics damping="0.5" friction="0"/>
  </joint>
  <link name="Right_Thumb_Phamed">
    <inertial>
      <origin rpy="0 0 0" xyz="0.0062 -0.00191 0"/>
      <mass value="0.0253"/>
      <inertia ixx="2.02829e-6" ixy="1.59416e-7" ixz="-6.0098e-8" iyy="3.0874e-6" iyz="1.3730e-8" izz="3.3672e-6"/>
    </inertial>
    <visual>
      <origin rpy="0 0 0" xyz="0 0 0"/>
      <geometry>
        <mesh filename="./meshes/visual/tekken/finger-phamed.dae"/>
      </geometry>
      <!--       <material name="phamed_color"/>  -->
    </visual>
    <collision>
      <origin rpy="0 0 0" xyz="0 0 0"/>
      <geometry>
        <mesh filename="./meshes/collision/tekken/finger-phamed.obj"/>
      </geometry>
    </collision>
  </link>
  <!-- +++++ Finger joint 3 Phalanx distalis ++++++ -->
  <joint name="Right_Thumb_3" type="revolute">
    <origin rpy="0 0 -1.570796" xyz="0.025 0 0"/>
    <parent link="Right_Thumb_Phamed"/>
    <child link="Right_Thumb_Phadist"/>
    <axis xyz="0 0 1"/>
    <limit effort="0.35" lower="0.0" upper="1.13446" velocity="3.14"/>
    <!-- Effort limit based on max fingertip force of 10N. Finger tip is approx 3.5cm away from this joint.-->
    <dynamics damping="0.5" friction="0"/>
  </joint>
  <link name="Right_Thumb_Phadist">
    <inertial>
      <origin rpy="0 0 0" xyz="0.00196 0.00724 0.0"/>
      <mass value="0.0137"/>
      <inertia ixx="2.6704e-6" ixy=" -8.084e-8" ixz="0.0" iyy="1.4985e-6" iyz="1.915e-7" izz=" 4.0842e-6"/>
    </inertial>
    <visual>
      <origin rpy="0 0 0" xyz="0 0 0"/>
      <geometry>
        <mesh filename="./meshes/visual/tekken/finger-phadist.dae"/>
      </geometry>
      <!-- <material name="phadist_color"/> -->
    </visual>
    <collision>
      <origin rpy="0 0 0" xyz="0 0 0"/>
      <geometry>
        <mesh filename="./meshes/collision/tekken/finger-phadist.obj"/>
      </geometry>
    </collision>
  </link>
  <!-- +++++ Finger base joint 0 ++++++ -->
  <joint name="Right_Index_0" type="revolute">
    <!-- joint origin in parent link frame -->
    <origin rpy="3.054326 -1.570796 0.000000" xyz="-0.002529881 0.03680013 0.107783545"/>
    <parent link="base_link_hithand"/>
    <child link="Right_Index_Basecover"/>
    <axis xyz="0 0 1"/>
    <limit effort="15" lower="-0.261799" upper="0.261799" velocity="3.14"/>
    <dynamics damping="0.5" friction="0"/>
  </joint>
  <link name="Right_Index_Basecover">
    <inertial>
      <origin rpy="0 0 0" xyz="0.02749 0 0"/>
      <mass value="0.0176"/>
      <inertia ixx="1.3450e-6" ixy="0.0" ixz="-1.8183e-7" iyy="1.9874e-6" iyz="0.0" izz="1.0419e-6"/>
    </inertial>
    <visual>
      <origin rpy="0 0 0" xyz="0 0 0"/>
      <geometry>
        <mesh filename="./meshes/visual/tekken/finger-basecover.dae"/>
      </geometry>
      <!-- <material name="phaprox_color"/> -->
    </visual>
    <collision>
      <origin rpy="0 0 0" xyz="0 0 0"/>
      <geometry name="hithand_Index_base_cover">
        <cylinder length="0.001" radius="0.001"/>
      </geometry>
    </collision>
  </link>
  <!-- +++++ Finger joint 1, Link: Phalanx proximalis ++++++ -->
  <joint name="Right_Index_1" type="revolute">
    <origin rpy="1.5708 0 0" xyz="0 0 0 "/>
    <parent link="Right_Index_Basecover"/>
    <child link="Right_Index_Phaprox"/>
    <axis xyz="0 0 1"/>
    <limit effort="1.15" lower="0.0" upper="1.48353" velocity="3.14"/>
    <!-- Effort limit based on max fingertip force of 10N. Finger tip is approx 11.5cm away from this joint.-->
    <dynamics damping="0.5" friction="0"/>
  </joint>
  <link name="Right_Index_Phaprox">
    <inertial>
      <origin rpy="0 0 0" xyz="0.02516 -0.0019 0"/>
      <mass value="0.0571"/>
      <inertia ixx="5.7609e-6" ixy="-4.3826e-7" ixz="-3.2556e-7" iyy="1.5809e-5" iyz="-4.516e-8" izz="1.8139e-5"/>
    </inertial>
    <visual>
      <origin rpy="0 0 0" xyz="0 0 0"/>
      <geometry>
        <mesh filename="./meshes/visual/tekken/finger-phaprox.dae"/>
      </geometry>
      <!-- <material name="phaprox_color"/> -->
    </visual>
    <collision>
      <origin rpy="0 0 0" xyz="0 0 0"/>
      <geometry>
        <mesh filename="./meshes/collision/tekken/finger-phaprox.obj"/>
      </geometry>
    </collision>
  </link>
  <!-- +++++ Finger joint 2 Phalanx medialis ++++++ -->
  <joint name="Right_Index_2" type="revolute">
    <origin rpy="0 0 0" xyz="0.055 0 0"/>
    <parent link="Right_Index_Phaprox"/>
    <child link="Right_Index_Phamed"/>
    <axis xyz="0 0 1"/>
    <limit effort="0.6" lower="0.0" upper="1.13446" velocity="3.14"/>
    <!-- Effort limit based on max fingertip force of 10N. Finger tip is approx 6cm away from this joint.-->
    <dynamics damping="0.5" friction="0"/>
  </joint>
  <link name="Right_Index_Phamed">
    <inertial>
      <origin rpy="0 0 0" xyz="0.0062 -0.00191 0"/>
      <mass value="0.0253"/>
      <inertia ixx="2.02829e-6" ixy="1.59416e-7" ixz="-6.0098e-8" iyy="3.0874e-6" iyz="1.3730e-8" izz="3.3672e-6"/>
    </inertial>
    <visual>
      <origin rpy="0 0 0" xyz="0 0 0"/>
      <geometry>
        <mesh filename="./meshes/visual/tekken/finger-phamed.dae"/>
      </geometry>
      <!--       <material name="phamed_color"/> -->
    </visual>
    <collision>
      <origin rpy="0 0 0" xyz="0 0 0"/>
      <geometry>
        <mesh filename="./meshes/collision/tekken/finger-phamed.obj"/>
      </geometry>
    </collision>
  </link>
  <!-- +++++ Finger joint 3 Phalanx distalis ++++++ -->
  <joint name="Right_Index_3" type="revolute">
    <origin rpy="0 0 -1.570796" xyz="0.025 0 0"/>
    <parent link="Right_Index_Phamed"/>
    <child link="Right_Index_Phadist"/>
    <axis xyz="0 0 1"/>
    <limit effort="0.35" lower="0.0" upper="1.13446" velocity="3.14"/>
    <!-- Effort limit based on max fingertip force of 10N. Finger tip is approx 3.5cm away from this joint.-->
    <dynamics damping="0.5" friction="0"/>
  </joint>
  <link name="Right_Index_Phadist">
    <inertial>
      <origin rpy="0 0 0" xyz="0.00196 0.00724 0.0"/>
      <mass value="0.0137"/>
      <inertia ixx="2.6704e-6" ixy=" -8.084e-8" ixz="0.0" iyy="1.4985e-6" iyz="1.915e-7" izz=" 4.0842e-6"/>
    </inertial>
    <visual>
      <origin rpy="0 0 0" xyz="0 0 0"/>
      <geometry>
        <mesh filename="./meshes/visual/tekken/finger-phadist.dae"/>
      </geometry>
      <!-- <material name="phadist_color"/> -->
    </visual>
    <collision>
      <origin rpy="0 0 0" xyz="0 0 0"/>
      <geometry>
        <mesh filename="./meshes/collision/tekken/finger-phadist.obj"/>
      </geometry>
    </collision>
  </link>
  <!-- +++++ Finger base joint 0 ++++++ -->
  <joint name="Right_Middle_0" type="revolute">
    <!-- joint origin in parent link frame -->
    <origin rpy="-3.141593 -1.570796 0.000000" xyz="-0.0037 0.01  0.117783545"/>
    <parent link="base_link_hithand"/>
    <child link="Right_Middle_Basecover"/>
    <axis xyz="0 0 1"/>
    <limit effort="15" lower="-0.261799" upper="0.261799" velocity="3.14"/>
    <dynamics damping="0.5" friction="0"/>
  </joint>
  <link name="Right_Middle_Basecover">
    <inertial>
      <origin rpy="0 0 0" xyz="0.02749 0 0"/>
      <mass value="0.0176"/>
      <inertia ixx="1.3450e-6" ixy="0.0" ixz="-1.8183e-7" iyy="1.9874e-6" iyz="0.0" izz="1.0419e-6"/>
    </inertial>
    <visual>
      <origin rpy="0 0 0" xyz="0 0 0"/>
      <geometry>
        <mesh filename="./meshes/visual/tekken/finger-basecover.dae"/>
      </geometry>
      <!-- <material name="phaprox_color"/> -->
    </visual>
    <collision>
      <origin rpy="0 0 0" xyz="0 0 0"/>
      <geometry name="hithand_Middle_base_cover">
        <cylinder length="0.001" radius="0.001"/>
      </geometry>
    </collision>
  </link>
  <!-- +++++ Finger joint 1, Link: Phalanx proximalis ++++++ -->
  <joint name="Right_Middle_1" type="revolute">
    <origin rpy="1.5708 0 0" xyz="0 0 0 "/>
    <parent link="Right_Middle_Basecover"/>
    <child link="Right_Middle_Phaprox"/>
    <axis xyz="0 0 1"/>
    <limit effort="1.15" lower="0.0" upper="1.48353" velocity="3.14"/>
    <!-- Effort limit based on max fingertip force of 10N. Finger tip is approx 11.5cm away from this joint.-->
    <dynamics damping="0.5" friction="0"/>
  </joint>
  <link name="Right_Middle_Phaprox">
    <inertial>
      <origin rpy="0 0 0" xyz="0.02516 -0.0019 0"/>
      <mass value="0.0571"/>
      <inertia ixx="5.7609e-6" ixy="-4.3826e-7" ixz="-3.2556e-7" iyy="1.5809e-5" iyz="-4.516e-8" izz="1.8139e-5"/>
    </inertial>
    <visual>
      <origin rpy="0 0 0" xyz="0 0 0"/>
      <geometry>
        <mesh filename="./meshes/visual/tekken/finger-phaprox.dae"/>
      </geometry>
      <!-- <material name="phaprox_color"/> -->
    </visual>
    <collision>
      <origin rpy="0 0 0" xyz="0 0 0"/>
      <geometry>
        <mesh filename="./meshes/collision/tekken/finger-phaprox.obj"/>
      </geometry>
    </collision>
  </link>
  <!-- +++++ Finger joint 2 Phalanx medialis ++++++ -->
  <joint name="Right_Middle_2" type="revolute">
    <origin rpy="0 0 0" xyz="0.055 0 0"/>
    <parent link="Right_Middle_Phaprox"/>
    <child link="Right_Middle_Phamed"/>
    <axis xyz="0 0 1"/>
    <limit effort="0.6" lower="0.0" upper="1.13446" velocity="3.14"/>
    <!-- Effort limit based on max fingertip force of 10N. Finger tip is approx 6cm away from this joint.-->
    <dynamics damping="0.5" friction="0"/>
  </joint>
  <link name="Right_Middle_Phamed">
    <inertial>
      <origin rpy="0 0 0" xyz="0.0062 -0.00191 0"/>
      <mass value="0.0253"/>
      <inertia ixx="2.02829e-6" ixy="1.59416e-7" ixz="-6.0098e-8" iyy="3.0874e-6" iyz="1.3730e-8" izz="3.3672e-6"/>
    </inertial>
    <visual>
      <origin rpy="0 0 0" xyz="0 0 0"/>
      <geometry>
        <mesh filename="./meshes/visual/tekken/finger-phamed.dae"/>
      </geometry>
      <!--       <material name="phamed_color"/>  -->
    </visual>
    <collision>
      <origin rpy="0 0 0" xyz="0 0 0"/>
      <geometry>
        <mesh filename="./meshes/collision/tekken/finger-phamed.obj"/>
      </geometry>
    </collision>
  </link>
  <!-- +++++ Finger joint 3 Phalanx distalis ++++++ -->
  <joint name="Right_Middle_3" type="revolute">
    <origin rpy="0 0 -1.570796" xyz="0.025 0 0"/>
    <parent link="Right_Middle_Phamed"/>
    <child link="Right_Middle_Phadist"/>
    <axis xyz="0 0 1"/>
    <limit effort="0.35" lower="0.0" upper="1.13446" velocity="3.14"/>
    <!-- Effort limit based on max fingertip force of 10N. Finger tip is approx 3.5cm away from this joint.-->
    <dynamics damping="0.5" friction="0"/>
  </joint>
  <link name="Right_Middle_Phadist">
    <inertial>
      <origin rpy="0 0 0" xyz="0.00196 0.00724 0.0"/>
      <mass value="0.0137"/>
      <inertia ixx="2.6704e-6" ixy=" -8.084e-8" ixz="0.0" iyy="1.4985e-6" iyz="1.915e-7" izz=" 4.0842e-6"/>
    </inertial>
    <visual>
      <origin rpy="0 0 0" xyz="0 0 0"/>
      <geometry>
        <mesh filename="./meshes/visual/tekken/finger-phadist.dae"/>
      </geometry>
      <!-- <material name="phadist_color"/> -->
    </visual>
    <collision>
      <origin rpy="0 0 0" xyz="0 0 0"/>
      <geometry>
        <mesh filename="./meshes/collision/tekken/finger-phadist.obj"/>
      </geometry>
    </collision>
  </link>
  <!-- +++++ Finger base joint 0 ++++++ -->
  <joint name="Right_Ring_0" type="revolute">
    <!-- joint origin in parent link frame -->
    <origin rpy="-3.054326 -1.570796 0.000000" xyz="0 -0.01680013 0.11258354"/>
    <parent link="base_link_hithand"/>
    <child link="Right_Ring_Basecover"/>
    <axis xyz="0 0 1"/>
    <limit effort="15" lower="-0.261799" upper="0.261799" velocity="3.14"/>
    <dynamics damping="0.5" friction="0"/>
  </joint>
  <link name="Right_Ring_Basecover">
    <inertial>
      <origin rpy="0 0 0" xyz="0.02749 0 0"/>
      <mass value="0.0176"/>
      <inertia ixx="1.3450e-6" ixy="0.0" ixz="-1.8183e-7" iyy="1.9874e-6" iyz="0.0" izz="1.0419e-6"/>
    </inertial>
    <visual>
      <origin rpy="0 0 0" xyz="0 0 0"/>
      <geometry>
        <mesh filename="./meshes/visual/tekken/finger-basecover.dae"/>
      </geometry>
      <!-- <material name="phaprox_color"/> -->
    </visual>
    <collision>
      <origin rpy="0 0 0" xyz="0 0 0"/>
      <geometry name="hithand_Ring_base_cover">
        <cylinder length="0.001" radius="0.001"/>
      </geometry>
    </collision>
  </link>
  <!-- +++++ Finger joint 1, Link: Phalanx proximalis ++++++ -->
  <joint name="Right_Ring_1" type="revolute">
    <origin rpy="1.5708 0 0" xyz="0 0 0 "/>
    <parent link="Right_Ring_Basecover"/>
    <child link="Right_Ring_Phaprox"/>
    <axis xyz="0 0 1"/>
    <limit effort="1.15" lower="0.0" upper="1.48353" velocity="3.14"/>
    <!-- Effort limit based on max fingertip force of 10N. Finger tip is approx 11.5cm away from this joint.-->
    <dynamics damping="0.5" friction="0"/>
  </joint>
  <link name="Right_Ring_Phaprox">
    <inertial>
      <origin rpy="0 0 0" xyz="0.02516 -0.0019 0"/>
      <mass value="0.0571"/>
      <inertia ixx="5.7609e-6" ixy="-4.3826e-7" ixz="-3.2556e-7" iyy="1.5809e-5" iyz="-4.516e-8" izz="1.8139e-5"/>
    </inertial>
    <visual>
      <origin rpy="0 0 0" xyz="0 0 0"/>
      <geometry>
        <mesh filename="./meshes/visual/tekken/finger-phaprox.dae"/>
      </geometry>
      <!-- <material name="phaprox_color"/> -->
    </visual>
    <collision>
      <origin rpy="0 0 0" xyz="0 0 0"/>
      <geometry>
        <mesh filename="./meshes/collision/tekken/finger-phaprox.obj"/>
      </geometry>
    </collision>
  </link>
  <!-- +++++ Finger joint 2 Phalanx medialis ++++++ -->
  <joint name="Right_Ring_2" type="revolute">
    <origin rpy="0 0 0" xyz="0.055 0 0"/>
    <parent link="Right_Ring_Phaprox"/>
    <child link="Right_Ring_Phamed"/>
    <axis xyz="0 0 1"/>
    <limit effort="0.6" lower="0.0" upper="1.13446" velocity="3.14"/>
    <!-- Effort limit based on max fingertip force of 10N. Finger tip is approx 6cm away from this joint.-->
    <dynamics damping="0.5" friction="0"/>
  </joint>
  <link name="Right_Ring_Phamed">
    <inertial>
      <origin rpy="0 0 0" xyz="0.0062 -0.00191 0"/>
      <mass value="0.0253"/>
      <inertia ixx="2.02829e-6" ixy="1.59416e-7" ixz="-6.0098e-8" iyy="3.0874e-6" iyz="1.3730e-8" izz="3.3672e-6"/>
    </inertial>
    <visual>
      <origin rpy="0 0 0" xyz="0 0 0"/>
      <geometry>
        <mesh filename="./meshes/visual/tekken/finger-phamed.dae"/>
      </geometry>
      <!--       <material name="phamed_color"/>  -->
    </visual>
    <collision>
      <origin rpy="0 0 0" xyz="0 0 0"/>
      <geometry>
        <mesh filename="./meshes/collision/tekken/finger-phamed.obj"/>
      </geometry>
    </collision>
  </link>
  <!-- +++++ Finger joint 3 Phalanx distalis ++++++ -->
  <joint name="Right_Ring_3" type="revolute">
    <origin rpy="0 0 -1.570796" xyz="0.025 0 0"/>
    <parent link="Right_Ring_Phamed"/>
    <child link="Right_Ring_Phadist"/>
    <axis xyz="0 0 1"/>
    <limit effort="0.35" lower="0.0" upper="1.13446" velocity="3.14"/>
    <!-- Effort limit based on max fingertip force of 10N. Finger tip is approx 3.5cm away from this joint.-->
    <dynamics damping="0.5" friction="0"/>
  </joint>
  <link name="Right_Ring_Phadist">
    <inertial>
      <origin rpy="0 0 0" xyz="0.00196 0.00724 0.0"/>
      <mass value="0.0137"/>
      <inertia ixx="2.6704e-6" ixy=" -8.084e-8" ixz="0.0" iyy="1.4985e-6" iyz="1.915e-7" izz=" 4.0842e-6"/>
    </inertial>
    <visual>
      <origin rpy="0 0 0" xyz="0 0 0"/>
      <geometry>
        <mesh filename="./meshes/visual/tekken/finger-phadist.dae"/>
      </geometry>
      <!-- <material name="phadist_color"/> -->
    </visual>
    <collision>
      <origin rpy="0 0 0" xyz="0 0 0"/>
      <geometry>
        <mesh filename="./meshes/collision/tekken/finger-phadist.obj"/>
      </geometry>
    </collision>
  </link>
  <!-- +++++ Finger base joint 0 ++++++ -->
  <joint name="Right_Little_0" type="revolute">
    <!-- joint origin in parent link frame -->
    <origin rpy="-2.967060 -1.570796 0.000000" xyz="0.000971571 -0.0433963 0.093583545"/>
    <parent link="base_link_hithand"/>
    <child link="Right_Little_Basecover"/>
    <axis xyz="0 0 1"/>
    <limit effort="15" lower="-0.261799" upper="0.261799" velocity="3.14"/>
    <dynamics damping="0.5" friction="0"/>
  </joint>
  <link name="Right_Little_Basecover">
    <inertial>
      <origin rpy="0 0 0" xyz="0.02749 0 0"/>
      <mass value="0.0176"/>
      <inertia ixx="1.3450e-6" ixy="0.0" ixz="-1.8183e-7" iyy="1.9874e-6" iyz="0.0" izz="1.0419e-6"/>
    </inertial>
    <visual>
      <origin rpy="0 0 0" xyz="0 0 0"/>
      <geometry>
        <mesh filename="./meshes/visual/tekken/finger-basecover.dae"/>
      </geometry>
      <!-- <material name="phaprox_color"/> -->
    </visual>
    <collision>
      <origin rpy="0 0 0" xyz="0 0 0"/>
      <geometry name="hithand_Little_base_cover">
        <cylinder length="0.001" radius="0.001"/>
      </geometry>
    </collision>
  </link>
  <!-- +++++ Finger joint 1, Link: Phalanx proximalis ++++++ -->
  <joint name="Right_Little_1" type="revolute">
    <origin rpy="1.5708 0 0" xyz="0 0 0 "/>
    <parent link="Right_Little_Basecover"/>
    <child link="Right_Little_Phaprox"/>
    <axis xyz="0 0 1"/>
    <limit effort="1.15" lower="0.0" upper="1.48353" velocity="3.14"/>
    <!-- Effort limit based on max fingertip force of 10N. Finger tip is approx 11.5cm away from this joint.-->
    <dynamics damping="0.5" friction="0"/>
  </joint>
  <link name="Right_Little_Phaprox">
    <inertial>
      <origin rpy="0 0 0" xyz="0.02516 -0.0019 0"/>
      <mass value="0.0571"/>
      <inertia ixx="5.7609e-6" ixy="-4.3826e-7" ixz="-3.2556e-7" iyy="1.5809e-5" iyz="-4.516e-8" izz="1.8139e-5"/>
    </inertial>
    <visual>
      <origin rpy="0 0 0" xyz="0 0 0"/>
      <geometry>
        <mesh filename="./meshes/visual/tekken/finger-phaprox.dae"/>
      </geometry>
      <!-- <material name="phaprox_color"/> -->
    </visual>
    <collision>
      <origin rpy="0 0 0" xyz="0 0 0"/>
      <geometry>
        <mesh filename="./meshes/collision/tekken/finger-phaprox.obj"/>
      </geometry>
    </collision>
  </link>
  <!-- +++++ Finger joint 2 Phalanx medialis ++++++ -->
  <joint name="Right_Little_2" type="revolute">
    <origin rpy="0 0 0" xyz="0.055 0 0"/>
    <parent link="Right_Little_Phaprox"/>
    <child link="Right_Little_Phamed"/>
    <axis xyz="0 0 1"/>
    <limit effort="0.6" lower="0.0" upper="1.13446" velocity="3.14"/>
    <!-- Effort limit based on max fingertip force of 10N. Finger tip is approx 6cm away from this joint.-->
    <dynamics damping="0.5" friction="0"/>
  </joint>
  <link name="Right_Little_Phamed">
    <inertial>
      <origin rpy="0 0 0" xyz="0.0062 -0.00191 0"/>
      <mass value="0.0253"/>
      <inertia ixx="2.02829e-6" ixy="1.59416e-7" ixz="-6.0098e-8" iyy="3.0874e-6" iyz="1.3730e-8" izz="3.3672e-6"/>
    </inertial>
    <visual>
      <origin rpy="0 0 0" xyz="0 0 0"/>
      <geometry>
        <mesh filename="./meshes/visual/tekken/finger-phamed.dae"/>
      </geometry>
      <!--       <material name="phamed_color"/>  -->
    </visual>
    <collision>
      <origin rpy="0 0 0" xyz="0 0 0"/>
      <geometry>
        <mesh filename="./meshes/collision/tekken/finger-phamed.obj"/>
      </geometry>
    </collision>
  </link>
  <!-- +++++ Finger joint 3 Phalanx distalis ++++++ -->
  <joint name="Right_Little_3" type="revolute">
    <origin rpy="0 0 -1.570796" xyz="0.025 0 0"/>
    <parent link="Right_Little_Phamed"/>
    <child link="Right_Little_Phadist"/>
    <axis xyz="0 0 1"/>
    <limit effort="0.35" lower="0.0" upper="1.13446" velocity="3.14"/>
    <!-- Effort limit based on max fingertip force of 10N. Finger tip is approx 3.5cm away from this joint.-->
    <dynamics damping="0.5" friction="0"/>
  </joint>
  <link name="Right_Little_Phadist">
    <inertial>
      <origin rpy="0 0 0" xyz="0.00196 0.00724 0.0"/>
      <mass value="0.0137"/>
      <inertia ixx="2.6704e-6" ixy=" -8.084e-8" ixz="0.0" iyy="1.4985e-6" iyz="1.915e-7" izz=" 4.0842e-6"/>
    </inertial>
    <visual>
      <origin rpy="0 0 0" xyz="0 0 0"/>
      <geometry>
        <mesh filename="./meshes/visual/tekken/finger-phadist.dae"/>
      </geometry>
      <!-- <material name="phadist_color"/> -->
    </visual>
    <collision>
      <origin rpy="0 0 0" xyz="0 0 0"/>
      <geometry>
        <mesh filename="./meshes/collision/tekken/finger-phadist.obj"/>
      </geometry>
    </collision>
  </link>
</robot>
